<?xml version="1.0" ?>
<robot name="right-pull-door">
	<link name="base"/>
	<link name="link_0">
		<visual name="out-frame">
			<origin xyz="0 0 0"/>
			<geometry>
				<mesh filename="texture_dae/frame.dae" scale="1.1723561352424483 1.1723561352424483 1.1723561352424483"/>
			</geometry>
		</visual>
		<collision>
			<origin xyz="0 0 0"/>
			<geometry>
				<mesh filename="texture_dae/frame.dae" scale="1.1723561352424483 1.1723561352424483 1.1723561352424483"/>
			</geometry>
		</collision>
	</link>
	<joint name="joint_0" type="fixed">
		<origin rpy="1.570796326794897 0 -1.570796326794897" xyz="0 0 0"/>
		<child link="link_0"/>
		<parent link="base"/>
	</joint>
	<link name="link_1">
		<visual name="surf-board">
			<origin xyz="0.37208866296310894 -0.8924036705471254 0"/>
			<geometry>
				<mesh filename="texture_dae/board.dae" scale="1.1723561352424483 1.1723561352424483 1.1723561352424483"/>
			</geometry>
		</visual>
		<collision>
			<origin xyz="0.37208866296310894 -0.8924036705471254 0"/>
			<geometry>
				<mesh filename="texture_dae/board.dae" scale="1.1723561352424483 1.1723561352424483 1.1723561352424483"/>
			</geometry>
		</collision>
	</link>
	<joint name="joint_1" type="revolute">
		<origin xyz="-0.37208866296310894 0.8924036705471254 0"/>
		<axis xyz="0 -1 0"/>
		<child link="link_1"/>
		<parent link="link_0"/>
		<limit lower="0" upper="1.5079644737231006"/>
	</joint>
	<link name="link_2">
		<visual name="handle">
			<origin xyz="0 0 0"/>
			<geometry>
				<mesh filename="texture_dae/9962029.dae" scale="1.257091943365646 1.257091943365646 1.257091943365646"/>
			</geometry>
		</visual>
		<collision>
			<origin xyz="0 0 0"/>
			<geometry>
				<mesh filename="texture_dae/9962029.dae" scale="1.257091943365646 1.257091943365646 1.257091943365646"/>
			</geometry>
		</collision>
	</link>
	<joint name="joint_2" type="revolute">
		<origin xyz="0.6633066967782667 -1.036740942427777 0.01747306361613137"/>
		<child link="link_2"/>
		<parent link="link_1"/>
		<axis xyz="0 0 1"/>
		<limit lower="0" upper="1.5079644737231006"/>
	</joint>
</robot>
