<?xml version="1.0" ?>
<robot name="right-pull-door">
	<link name="base"/>
	<link name="link_0">
		<visual name="out-frame">
			<origin xyz="0 0 0"/>
			<geometry>
				<mesh filename="texture_dae/frame.dae" scale="0.8465597374264098 0.8465597374264098 0.8465597374264098"/>
			</geometry>
		</visual>
		<collision>
			<origin xyz="0 0 0"/>
			<geometry>
				<mesh filename="texture_dae/frame.dae" scale="0.8465597374264098 0.8465597374264098 0.8465597374264098"/>
			</geometry>
		</collision>
	</link>
	<joint name="joint_0" type="fixed">
		<origin rpy="1.570796326794897 0 -1.570796326794897" xyz="0 0 0"/>
		<child link="link_0"/>
		<parent link="base"/>
	</joint>
	<link name="link_1">
		<visual name="surf-board">
			<origin xyz="0.32262050854279456 -0.8455630568299108 0"/>
			<geometry>
				<mesh filename="texture_dae/board.dae" scale="0.8465597374264098 0.8465597374264098 0.8465597374264098"/>
			</geometry>
		</visual>
		<collision>
			<origin xyz="0.32262050854279456 -0.8455630568299108 0"/>
			<geometry>
				<mesh filename="texture_dae/board.dae" scale="0.8465597374264098 0.8465597374264098 0.8465597374264098"/>
			</geometry>
		</collision>
	</link>
	<joint name="joint_1" type="revolute">
		<origin xyz="-0.32262050854279456 0.8455630568299108 0"/>
		<axis xyz="0 -1 0"/>
		<child link="link_1"/>
		<parent link="link_0"/>
		<limit lower="0" upper="1.5079644737231006"/>
	</joint>
	<link name="link_2">
		<visual name="handle">
			<origin xyz="0 0 0"/>
			<geometry>
				<mesh filename="texture_dae/9962014.dae" scale="1.0073357010285338 1.0073357010285338 1.0073357010285338"/>
			</geometry>
		</visual>
		<collision>
			<origin xyz="0 0 0"/>
			<geometry>
				<mesh filename="texture_dae/9962014.dae" scale="1.0073357010285338 1.0073357010285338 1.0073357010285338"/>
			</geometry>
		</collision>
	</link>
	<joint name="joint_2" type="revolute">
		<origin xyz="0.5650785121230291 -0.920209365661401 0.01336277858109595"/>
		<child link="link_2"/>
		<parent link="link_1"/>
		<axis xyz="0 0 1"/>
		<limit lower="0" upper="1.5079644737231006"/>
	</joint>
</robot>
