<?xml version="1.0" ?>
<robot name="right-pull-door">
	<link name="base"/>
	<link name="link_0">
		<visual name="out-frame">
			<origin xyz="0 0 0"/>
			<geometry>
				<mesh filename="texture_dae/frame.dae" scale="0.7385647294113814 0.7385647294113814 0.7385647294113814"/>
			</geometry>
		</visual>
		<collision>
			<origin xyz="0 0 0"/>
			<geometry>
				<mesh filename="texture_dae/frame.dae" scale="0.7385647294113814 0.7385647294113814 0.7385647294113814"/>
			</geometry>
		</collision>
	</link>
	<joint name="joint_0" type="fixed">
		<origin rpy="1.570796326794897 0 -1.570796326794897" xyz="0 0 0"/>
		<child link="link_0"/>
		<parent link="base"/>
	</joint>
	<link name="link_1">
		<visual name="surf-board">
			<origin xyz="0.2948917882924568 -0.8479565114682159 0"/>
			<geometry>
				<mesh filename="texture_dae/board.dae" scale="0.7385647294113814 0.7385647294113814 0.7385647294113814"/>
			</geometry>
		</visual>
		<collision>
			<origin xyz="0.2948917882924568 -0.8479565114682159 0"/>
			<geometry>
				<mesh filename="texture_dae/board.dae" scale="0.7385647294113814 0.7385647294113814 0.7385647294113814"/>
			</geometry>
		</collision>
	</link>
	<joint name="joint_1" type="revolute">
		<origin xyz="-0.2948917882924568 0.8479565114682159 0"/>
		<axis xyz="0 -1 0"/>
		<child link="link_1"/>
		<parent link="link_0"/>
		<limit lower="0" upper="1.5079644737231006"/>
	</joint>
	<link name="link_2">
		<visual name="handle">
			<origin xyz="0 0 0"/>
			<geometry>
				<mesh filename="texture_dae/9962024.dae" scale="1.4908545696326903 1.4908545696326903 1.4908545696326903"/>
			</geometry>
		</visual>
		<collision>
			<origin xyz="0 0 0"/>
			<geometry>
				<mesh filename="texture_dae/9962024.dae" scale="1.4908545696326903 1.4908545696326903 1.4908545696326903"/>
			</geometry>
		</collision>
	</link>
	<joint name="joint_2" type="revolute">
		<origin xyz="0.5108517093344074 -0.9722547823697163 0.028206380412217683"/>
		<child link="link_2"/>
		<parent link="link_1"/>
		<axis xyz="0 0 1"/>
		<limit lower="0" upper="1.5079644737231006"/>
	</joint>
</robot>
