<?xml version="1.0" ?>
<robot name="right-pull-door">
	<link name="base"/>
	<link name="link_0">
		<visual name="out-frame">
			<origin xyz="0 0 0"/>
			<geometry>
				<mesh filename="texture_dae/frame.dae" scale="1.1401096993775002 1.1401096993775002 1.1401096993775002"/>
			</geometry>
		</visual>
		<collision>
			<origin xyz="0 0 0"/>
			<geometry>
				<mesh filename="texture_dae/frame.dae" scale="1.1401096993775002 1.1401096993775002 1.1401096993775002"/>
			</geometry>
		</collision>
	</link>
	<joint name="joint_0" type="fixed">
		<origin rpy="1.570796326794897 0 -1.570796326794897" xyz="0 0 0"/>
		<child link="link_0"/>
		<parent link="base"/>
	</joint>
	<link name="link_1">
		<visual name="surf-board">
			<origin xyz="0.36185411661185635 -0.8678575135706952 0"/>
			<geometry>
				<mesh filename="texture_dae/board.dae" scale="1.1401096993775002 1.1401096993775002 1.1401096993775002"/>
			</geometry>
		</visual>
		<collision>
			<origin xyz="0.36185411661185635 -0.8678575135706952 0"/>
			<geometry>
				<mesh filename="texture_dae/board.dae" scale="1.1401096993775002 1.1401096993775002 1.1401096993775002"/>
			</geometry>
		</collision>
	</link>
	<joint name="joint_1" type="revolute">
		<origin xyz="-0.36185411661185635 0.8678575135706952 0"/>
		<axis xyz="0 -1 0"/>
		<child link="link_1"/>
		<parent link="link_0"/>
		<limit lower="0" upper="1.5079644737231006"/>
	</joint>
	<link name="link_2">
		<visual name="handle">
			<origin xyz="0 0 0"/>
			<geometry>
				<mesh filename="texture_dae/9960010.dae" scale="1.2842489731592692 1.2842489731592692 1.2842489731592692"/>
			</geometry>
		</visual>
		<collision>
			<origin xyz="0 0 0"/>
			<geometry>
				<mesh filename="texture_dae/9960010.dae" scale="1.2842489731592692 1.2842489731592692 1.2842489731592692"/>
			</geometry>
		</collision>
	</link>
	<joint name="joint_2" type="revolute">
		<origin xyz="0.64286155131 -0.9862201602012457 0.016992455370629916"/>
		<child link="link_2"/>
		<parent link="link_1"/>
		<axis xyz="0 0 1"/>
		<limit lower="0" upper="1.5079644737231006"/>
	</joint>
</robot>
