<?xml version="1.0" ?>
<robot name="right-pull-door">
	<link name="base"/>
	<link name="link_0">
		<visual name="out-frame">
			<origin xyz="0 0 0"/>
			<geometry>
				<mesh filename="texture_dae/frame.dae" scale="0.9819213144505309 0.9819213144505309 0.9819213144505309"/>
			</geometry>
		</visual>
		<collision>
			<origin xyz="0 0 0"/>
			<geometry>
				<mesh filename="texture_dae/frame.dae" scale="0.9819213144505309 0.9819213144505309 0.9819213144505309"/>
			</geometry>
		</collision>
	</link>
	<joint name="joint_0" type="fixed">
		<origin rpy="1.570796326794897 0 -1.570796326794897" xyz="0 0 0"/>
		<child link="link_0"/>
		<parent link="base"/>
	</joint>
	<link name="link_1">
		<visual name="surf-board">
			<origin xyz="0.31814110873760876 -0.9017513457001962 0"/>
			<geometry>
				<mesh filename="texture_dae/board.dae" scale="0.9819213144505309 0.9819213144505309 0.9819213144505309"/>
			</geometry>
		</visual>
		<collision>
			<origin xyz="0.31814110873760876 -0.9017513457001962 0"/>
			<geometry>
				<mesh filename="texture_dae/board.dae" scale="0.9819213144505309 0.9819213144505309 0.9819213144505309"/>
			</geometry>
		</collision>
	</link>
	<joint name="joint_1" type="revolute">
		<origin xyz="-0.31814110873760876 0.9017513457001962 0"/>
		<axis xyz="0 -1 0"/>
		<child link="link_1"/>
		<parent link="link_0"/>
		<limit lower="0" upper="1.5079644737231006"/>
	</joint>
	<link name="link_2">
		<visual name="handle">
			<origin xyz="0 0 0"/>
			<geometry>
				<mesh filename="texture_dae/9960048-handle-right.dae" scale="1.08209426137901 1.08209426137901 1.08209426137901"/>
			</geometry>
		</visual>
		<collision>
			<origin xyz="0 0 0"/>
			<geometry>
				<mesh filename="texture_dae/9960048-handle-right.dae" scale="1.08209426137901 1.08209426137901 1.08209426137901"/>
			</geometry>
		</collision>
	</link>
	<joint name="joint_2" type="revolute">
		<origin xyz="0 0 0"/>
		<child link="link_2"/>
		<parent link="link_3"/>
		<axis xyz="0 0 1"/>
		<limit lower="0" upper="1.5079644737231006"/>
	</joint>
	<link name="link_3">
		<visual name="lock">
			<origin xyz="0 0 0"/>
			<geometry>
				<mesh filename="texture_dae/9960048-lock-right.dae" scale="1.08209426137901 1.08209426137901 1.08209426137901"/>
			</geometry>
		</visual>
		<collision>
			<origin xyz="0 0 0"/>
			<geometry>
				<mesh filename="texture_dae/9960048-lock-right.dae" scale="1.08209426137901 1.08209426137901 1.08209426137901"/>
			</geometry>
		</collision>
	</link>
	<joint name="joint_3" type="fixed">
		<origin xyz="0.5559314066927609 -1.0073047304942444 0.011062137272129019"/>
		<child link="link_3"/>
		<parent link="link_1"/>
	</joint>
</robot>
