<?xml version="1.0" ?>
<robot name="right-pull-door">
	<link name="base"/>
	<link name="link_0">
		<visual name="out-frame">
			<origin xyz="0 0 0"/>
			<geometry>
				<mesh filename="texture_dae/frame.dae" scale="0.7901255040075449 0.7901255040075449 0.7901255040075449"/>
			</geometry>
		</visual>
		<collision>
			<origin xyz="0 0 0"/>
			<geometry>
				<mesh filename="texture_dae/frame.dae" scale="0.7901255040075449 0.7901255040075449 0.7901255040075449"/>
			</geometry>
		</collision>
	</link>
	<joint name="joint_0" type="fixed">
		<origin rpy="1.570796326794897 0 -1.570796326794897" xyz="0 0 0"/>
		<child link="link_0"/>
		<parent link="base"/>
	</joint>
	<link name="link_1">
		<visual name="surf-board">
			<origin xyz="0.3357920516797528 -0.9201635071880045 0"/>
			<geometry>
				<mesh filename="texture_dae/board.dae" scale="0.7901255040075449 0.7901255040075449 0.7901255040075449"/>
			</geometry>
		</visual>
		<collision>
			<origin xyz="0.3357920516797528 -0.9201635071880045 0"/>
			<geometry>
				<mesh filename="texture_dae/board.dae" scale="0.7901255040075449 0.7901255040075449 0.7901255040075449"/>
			</geometry>
		</collision>
	</link>
	<joint name="joint_1" type="revolute">
		<origin xyz="-0.3357920516797528 0.9201635071880045 0"/>
		<axis xyz="0 -1 0"/>
		<child link="link_1"/>
		<parent link="link_0"/>
		<limit lower="0" upper="1.5079644737231006"/>
	</joint>
	<link name="link_2">
		<visual name="handle">
			<origin xyz="0 0 0"/>
			<geometry>
				<mesh filename="texture_dae/9960028.dae" scale="0.987324084098373 0.987324084098373 0.987324084098373"/>
			</geometry>
		</visual>
		<collision>
			<origin xyz="0 0 0"/>
			<geometry>
				<mesh filename="texture_dae/9960028.dae" scale="0.987324084098373 0.987324084098373 0.987324084098373"/>
			</geometry>
		</collision>
	</link>
	<joint name="joint_2" type="revolute">
		<origin xyz="0.5653976444055568 -1.0686468842896064 0.04754959405029551"/>
		<child link="link_2"/>
		<parent link="link_1"/>
		<axis xyz="0 0 1"/>
		<limit lower="0" upper="1.5079644737231006"/>
	</joint>
</robot>
