<?xml version="1.0" ?>
<robot name="right_pull_door">
	<link name="base">
		<inertial>
			<origin xyz="0 0 0" rpy="0 0 0"/>
			<mass value="1000.0"/>
			<inertia ixx="1.0" ixy="0.0" ixz="0.0" iyy="1.0" iyz="0.0" izz="1.0"/>
		</inertial>
		<visual>
			<origin xyz="0 0 0"/>
			<geometry>
				<box size="0.01 0.01 0.01"/>
			</geometry>
		</visual>
		<collision>
			<origin xyz="0 0 0"/>
			<geometry>
				<box size="0.01 0.01 0.01"/>
			</geometry>
		</collision>
	</link>
	
	<link name="door_frame">
		<inertial>
			<origin xyz="0 0 1.0" rpy="0 0 0"/>
			<mass value="50.0"/>
			<inertia ixx="10.0" ixy="0.0" ixz="0.0" iyy="10.0" iyz="0.0" izz="10.0"/>
		</inertial>
		<visual>
			<origin xyz="0 0 1.0"/>
			<geometry>
				<box size="0.1 1.0 2.0"/>
			</geometry>
		</visual>
		<collision>
			<origin xyz="0 0 1.0"/>
			<geometry>
				<box size="0.1 1.0 2.0"/>
			</geometry>
		</collision>
	</link>
	
	<joint name="base_to_frame" type="fixed">
		<origin rpy="0 0 0" xyz="0 0 0"/>
		<child link="door_frame"/>
		<parent link="base"/>
	</joint>
	
	<link name="door_panel">
		<inertial>
			<origin xyz="0 0.5 1.0" rpy="0 0 0"/>
			<mass value="25.0"/>
			<inertia ixx="5.0" ixy="0.0" ixz="0.0" iyy="5.0" iyz="0.0" izz="5.0"/>
		</inertial>
		<visual>
			<origin xyz="0 0.4 1.0"/>
			<geometry>
				<box size="0.05 0.8 1.8"/>
			</geometry>
		</visual>
		<collision>
			<origin xyz="0 0.4 1.0"/>
			<geometry>
				<box size="0.05 0.8 1.8"/>
			</geometry>
		</collision>
	</link>
	
	<joint name="door_hinge" type="revolute">
		<origin xyz="0 0 0"/>
		<axis xyz="0 0 1"/>
		<child link="door_panel"/>
		<parent link="door_frame"/>
		<limit lower="0" upper="1.5708"/>
		<dynamics damping="0.1" friction="0.1"/>
	</joint>
	
	<link name="door_handle">
		<inertial>
			<origin xyz="0 0 0" rpy="0 0 0"/>
			<mass value="2.0"/>
			<inertia ixx="0.1" ixy="0.0" ixz="0.0" iyy="0.1" iyz="0.0" izz="0.1"/>
		</inertial>
		<visual>
			<origin xyz="0.1 0 0"/>
			<geometry>
				<cylinder radius="0.02" length="0.15"/>
			</geometry>
		</visual>
		<collision>
			<origin xyz="0.1 0 0"/>
			<geometry>
				<cylinder radius="0.02" length="0.15"/>
			</geometry>
		</collision>
	</link>
	
	<joint name="handle_joint" type="revolute">
		<origin xyz="0.05 0.7 1.0"/>
		<child link="door_handle"/>
		<parent link="door_panel"/>
		<axis xyz="0 0 1"/>
		<limit lower="0" upper="1.5708"/>
		<dynamics damping="0.05" friction="0.05"/>
	</joint>
</robot>
