<?xml version="1.0" ?>
<robot name="right-pull-door">
	<link name="base"/>
	<link name="link_0">
		<visual name="out-frame">
			<origin xyz="0 0 0"/>
			<geometry>
				<mesh filename="texture_dae/frame.dae" scale="0.8636458503017361 0.8636458503017361 0.8636458503017361"/>
			</geometry>
		</visual>
		<collision>
			<origin xyz="0 0 0"/>
			<geometry>
				<mesh filename="texture_dae/frame.dae" scale="0.8636458503017361 0.8636458503017361 0.8636458503017361"/>
			</geometry>
		</collision>
	</link>
	<joint name="joint_0" type="fixed">
		<origin rpy="1.570796326794897 0 -1.570796326794897" xyz="0 0 0"/>
		<child link="link_0"/>
		<parent link="base"/>
	</joint>
	<link name="link_1">
		<visual name="surf-board">
			<origin xyz="0.3808653180019082 -0.8992131637015617 0"/>
			<geometry>
				<mesh filename="texture_dae/board.dae" scale="0.8636458503017361 0.8636458503017361 0.8636458503017361"/>
			</geometry>
		</visual>
		<collision>
			<origin xyz="0.3808653180019082 -0.8992131637015617 0"/>
			<geometry>
				<mesh filename="texture_dae/board.dae" scale="0.8636458503017361 0.8636458503017361 0.8636458503017361"/>
			</geometry>
		</collision>
	</link>
	<joint name="joint_1" type="revolute">
		<origin xyz="-0.3808653180019082 0.8992131637015617 0"/>
		<axis xyz="0 -1 0"/>
		<child link="link_1"/>
		<parent link="link_0"/>
		<limit lower="0" upper="1.5079644737231006"/>
	</joint>
	<link name="link_2">
		<visual name="handle">
			<origin xyz="0 0 0"/>
			<geometry>
				<mesh filename="texture_dae/9960034.dae" scale="1.2040434243747393 1.2040434243747393 1.2040434243747393"/>
			</geometry>
		</visual>
		<collision>
			<origin xyz="0 0 0"/>
			<geometry>
				<mesh filename="texture_dae/9960034.dae" scale="1.2040434243747393 1.2040434243747393 1.2040434243747393"/>
			</geometry>
		</collision>
	</link>
	<joint name="joint_2" type="revolute">
		<origin xyz="0.6822970051326513 -1.0289645535898642 0.019948035520088774"/>
		<child link="link_2"/>
		<parent link="link_1"/>
		<axis xyz="0 0 1"/>
		<limit lower="0" upper="1.5079644737231006"/>
	</joint>
</robot>
