<?xml version="1.0" ?>
<robot name="right-pull-door">
	<link name="base"/>
	<link name="link_0">
		<visual name="out-frame">
			<origin xyz="0 0 0"/>
			<geometry>
				<mesh filename="texture_dae/frame.dae" scale="1.0499165061329483 1.0499165061329483 1.0499165061329483"/>
			</geometry>
		</visual>
		<collision>
			<origin xyz="0 0 0"/>
			<geometry>
				<mesh filename="texture_dae/frame.dae" scale="1.0499165061329483 1.0499165061329483 1.0499165061329483"/>
			</geometry>
		</collision>
	</link>
	<joint name="joint_0" type="fixed">
		<origin rpy="1.570796326794897 0 -1.570796326794897" xyz="0 0 0"/>
		<child link="link_0"/>
		<parent link="base"/>
	</joint>
	<link name="link_1">
		<visual name="surf-board">
			<origin xyz="0.35548661474075605 -0.9118568867319342 0"/>
			<geometry>
				<mesh filename="texture_dae/board.dae" scale="1.0499165061329483 1.0499165061329483 1.0499165061329483"/>
			</geometry>
		</visual>
		<collision>
			<origin xyz="0.35548661474075605 -0.9118568867319342 0"/>
			<geometry>
				<mesh filename="texture_dae/board.dae" scale="1.0499165061329483 1.0499165061329483 1.0499165061329483"/>
			</geometry>
		</collision>
	</link>
	<joint name="joint_1" type="revolute">
		<origin xyz="-0.35548661474075605 0.9118568867319342 0"/>
		<axis xyz="0 -1 0"/>
		<child link="link_1"/>
		<parent link="link_0"/>
		<limit lower="0" upper="1.5079644737231006"/>
	</joint>
	<link name="link_2">
		<visual name="handle">
			<origin xyz="0 0 0"/>
			<geometry>
				<mesh filename="texture_dae/9962026.dae" scale="0.8126980225668411 0.8126980225668411 0.8126980225668411"/>
			</geometry>
		</visual>
		<collision>
			<origin xyz="0 0 0"/>
			<geometry>
				<mesh filename="texture_dae/9962026.dae" scale="0.8126980225668411 0.8126980225668411 0.8126980225668411"/>
			</geometry>
		</collision>
	</link>
	<joint name="joint_2" type="revolute">
		<origin xyz="0.6310941617696302 -1.0419557225686051 0.012592001396840913"/>
		<child link="link_2"/>
		<parent link="link_1"/>
		<axis xyz="0 0 1"/>
		<limit lower="0" upper="1.5079644737231006"/>
	</joint>
</robot>
