<?xml version="1.0" ?>
<robot name="right-pull-door">
	<link name="base"/>
	<link name="link_0">
		<visual name="out-frame">
			<origin xyz="0 0 0"/>
			<geometry>
				<mesh filename="texture_dae/frame.dae" scale="0.9795504098760583 0.9795504098760583 0.9795504098760583"/>
			</geometry>
		</visual>
		<collision>
			<origin xyz="0 0 0"/>
			<geometry>
				<mesh filename="texture_dae/frame.dae" scale="0.9795504098760583 0.9795504098760583 0.9795504098760583"/>
			</geometry>
		</collision>
	</link>
	<joint name="joint_0" type="fixed">
		<origin rpy="1.570796326794897 0 -1.570796326794897" xyz="0 0 0"/>
		<child link="link_0"/>
		<parent link="base"/>
	</joint>
	<link name="link_1">
		<visual name="surf-board">
			<origin xyz="0.3173729390289638 -0.899574016051584 0"/>
			<geometry>
				<mesh filename="texture_dae/board.dae" scale="0.9795504098760583 0.9795504098760583 0.9795504098760583"/>
			</geometry>
		</visual>
		<collision>
			<origin xyz="0.3173729390289638 -0.899574016051584 0"/>
			<geometry>
				<mesh filename="texture_dae/board.dae" scale="0.9795504098760583 0.9795504098760583 0.9795504098760583"/>
			</geometry>
		</collision>
	</link>
	<joint name="joint_1" type="revolute">
		<origin xyz="-0.3173729390289638 0.899574016051584 0"/>
		<axis xyz="0 -1 0"/>
		<child link="link_1"/>
		<parent link="link_0"/>
		<limit lower="0" upper="1.5079644737231006"/>
	</joint>
	<link name="link_2">
		<visual name="handle">
			<origin xyz="0 0 0"/>
			<geometry>
				<mesh filename="texture_dae/9962040.dae" scale="0.9806814481372474 0.9806814481372474 0.9806814481372474"/>
			</geometry>
		</visual>
		<collision>
			<origin xyz="0 0 0"/>
			<geometry>
				<mesh filename="texture_dae/9962040.dae" scale="0.9806814481372474 0.9806814481372474 0.9806814481372474"/>
			</geometry>
		</collision>
	</link>
	<joint name="joint_2" type="revolute">
		<origin xyz="0.5543959143279553 -1.0029408909584947 0.011035427115748911"/>
		<child link="link_2"/>
		<parent link="link_1"/>
		<axis xyz="0 0 1"/>
		<limit lower="0" upper="1.5079644737231006"/>
	</joint>
</robot>
