<?xml version="1.0" ?>
<robot name="right-pull-door">
	<link name="base"/>
	<link name="link_0">
		<visual name="out-frame">
			<origin xyz="0 0 0"/>
			<geometry>
				<mesh filename="texture_dae/frame.dae" scale="1.0598661171004193 1.0598661171004193 1.0598661171004193"/>
			</geometry>
		</visual>
		<collision>
			<origin xyz="0 0 0"/>
			<geometry>
				<mesh filename="texture_dae/frame.dae" scale="1.0598661171004193 1.0598661171004193 1.0598661171004193"/>
			</geometry>
		</collision>
	</link>
	<joint name="joint_0" type="fixed">
		<origin rpy="1.570796326794897 0 -1.570796326794897" xyz="0 0 0"/>
		<child link="link_0"/>
		<parent link="base"/>
	</joint>
	<link name="link_1">
		<visual name="surf-board">
			<origin xyz="0.3602486203654256 -0.828960883888819 0"/>
			<geometry>
				<mesh filename="texture_dae/board.dae" scale="1.0598661171004193 1.0598661171004193 1.0598661171004193"/>
			</geometry>
		</visual>
		<collision>
			<origin xyz="0.3602486203654256 -0.828960883888819 0"/>
			<geometry>
				<mesh filename="texture_dae/board.dae" scale="1.0598661171004193 1.0598661171004193 1.0598661171004193"/>
			</geometry>
		</collision>
	</link>
	<joint name="joint_1" type="revolute">
		<origin xyz="-0.3602486203654256 0.828960883888819 0"/>
		<axis xyz="0 -1 0"/>
		<child link="link_1"/>
		<parent link="link_0"/>
		<limit lower="0" upper="1.5079644737231006"/>
	</joint>
	<link name="link_2">
		<visual name="handle">
			<origin xyz="0 0 0"/>
			<geometry>
				<mesh filename="texture_dae/9960036.dae" scale="0.6809731574572221 0.6809731574572221 0.6809731574572221"/>
			</geometry>
		</visual>
		<collision>
			<origin xyz="0 0 0"/>
			<geometry>
				<mesh filename="texture_dae/9960036.dae" scale="0.6809731574572221 0.6809731574572221 0.6809731574572221"/>
			</geometry>
		</collision>
	</link>
	<joint name="joint_2" type="revolute">
		<origin xyz="0.6410614907450497 -0.8979405695106533 0.035737196567831333"/>
		<child link="link_2"/>
		<parent link="link_1"/>
		<axis xyz="0 0 1"/>
		<limit lower="0" upper="1.5079644737231006"/>
	</joint>
</robot>
