<?xml version="1.0" ?>
<robot name="right-pull-door">
	<link name="base"/>
	<link name="link_0">
		<visual name="out-frame">
			<origin xyz="0 0 0"/>
			<geometry>
				<mesh filename="texture_dae/frame.dae" scale="0.991626804394781 0.991626804394781 0.991626804394781"/>
			</geometry>
		</visual>
		<collision>
			<origin xyz="0 0 0"/>
			<geometry>
				<mesh filename="texture_dae/frame.dae" scale="0.991626804394781 0.991626804394781 0.991626804394781"/>
			</geometry>
		</collision>
	</link>
	<joint name="joint_0" type="fixed">
		<origin rpy="1.570796326794897 0 -1.570796326794897" xyz="0 0 0"/>
		<child link="link_0"/>
		<parent link="base"/>
	</joint>
	<link name="link_1">
		<visual name="surf-board">
			<origin xyz="0.33185633688023636 -0.7711576597294252 0"/>
			<geometry>
				<mesh filename="texture_dae/board.dae" scale="0.991626804394781 0.991626804394781 0.991626804394781"/>
			</geometry>
		</visual>
		<collision>
			<origin xyz="0.33185633688023636 -0.7711576597294252 0"/>
			<geometry>
				<mesh filename="texture_dae/board.dae" scale="0.991626804394781 0.991626804394781 0.991626804394781"/>
			</geometry>
		</collision>
	</link>
	<joint name="joint_1" type="revolute">
		<origin xyz="-0.33185633688023636 0.7711576597294252 0"/>
		<axis xyz="0 -1 0"/>
		<child link="link_1"/>
		<parent link="link_0"/>
		<limit lower="0" upper="1.5079644737231006"/>
	</joint>
	<link name="link_2">
		<visual name="handle">
			<origin xyz="0 0 0"/>
			<geometry>
				<mesh filename="texture_dae/9962022.dae" scale="1.1036314089811892 1.1036314089811892 1.1036314089811892"/>
			</geometry>
		</visual>
		<collision>
			<origin xyz="0 0 0"/>
			<geometry>
				<mesh filename="texture_dae/9962022.dae" scale="1.1036314089811892 1.1036314089811892 1.1036314089811892"/>
			</geometry>
		</collision>
	</link>
	<joint name="joint_2" type="revolute">
		<origin xyz="0.5859200412144623 -0.8976016246346248 0.02568122153489867"/>
		<child link="link_2"/>
		<parent link="link_1"/>
		<axis xyz="0 0 1"/>
		<limit lower="0" upper="1.5079644737231006"/>
	</joint>
</robot>
