<?xml version="1.0" ?>
<robot name="right-pull-door">
	<link name="base"/>
	<link name="link_0">
		<visual name="out-frame">
			<origin xyz="0 0 0"/>
			<geometry>
				<mesh filename="texture_dae/frame.dae" scale="0.5842804225272118 0.5842804225272118 0.5842804225272118"/>
			</geometry>
		</visual>
		<collision>
			<origin xyz="0 0 0"/>
			<geometry>
				<mesh filename="texture_dae/frame.dae" scale="0.5842804225272118 0.5842804225272118 0.5842804225272118"/>
			</geometry>
		</collision>
	</link>
	<joint name="joint_0" type="fixed">
		<origin rpy="1.570796326794897 0 -1.570796326794897" xyz="0 0 0"/>
		<child link="link_0"/>
		<parent link="base"/>
	</joint>
	<link name="link_1">
		<visual name="surf-board">
			<origin xyz="0.41584500126917034 -0.5285524590076831 0"/>
			<geometry>
				<mesh filename="texture_dae/board.dae" scale="0.5842804225272118 0.5842804225272118 0.5842804225272118"/>
			</geometry>
		</visual>
		<collision>
			<origin xyz="0.41584500126917034 -0.5285524590076831 0"/>
			<geometry>
				<mesh filename="texture_dae/board.dae" scale="0.5842804225272118 0.5842804225272118 0.5842804225272118"/>
			</geometry>
		</collision>
	</link>
	<joint name="joint_1" type="revolute">
		<origin xyz="-0.41584500126917034 0.5285524590076831 0"/>
		<axis xyz="0 -1 0"/>
		<child link="link_1"/>
		<parent link="link_0"/>
		<limit lower="0" upper="1.5079644737231006"/>
	</joint>
	<link name="link_2">
		<visual name="handle">
			<origin xyz="0 0 0"/>
			<geometry>
				<mesh filename="texture_dae/9960017-handle-right.dae" scale="1.3816250201590838 1.3816250201590838 1.3816250201590838"/>
			</geometry>
		</visual>
		<collision>
			<origin xyz="0 0 0"/>
			<geometry>
				<mesh filename="texture_dae/9960017-handle-right.dae" scale="1.3816250201590838 1.3816250201590838 1.3816250201590838"/>
			</geometry>
		</collision>
	</link>
	<joint name="joint_2" type="revolute">
		<origin xyz="0 0 0"/>
		<child link="link_2"/>
		<parent link="link_3"/>
		<axis xyz="0 0 1"/>
		<limit lower="0" upper="1.5079644737231006"/>
	</joint>
	<link name="link_3">
		<visual name="lock">
			<origin xyz="0 0 0"/>
			<geometry>
				<mesh filename="texture_dae/9960017-lock-right.dae" scale="1.3816250201590838 1.3816250201590838 1.3816250201590838"/>
			</geometry>
		</visual>
		<collision>
			<origin xyz="0 0 0"/>
			<geometry>
				<mesh filename="texture_dae/9960017-lock-right.dae" scale="1.3816250201590838 1.3816250201590838 1.3816250201590838"/>
			</geometry>
		</collision>
	</link>
	<joint name="joint_3" type="fixed">
		<origin xyz="0.7556548389621719 -0.619801369463197 0.028906386734450045"/>
		<child link="link_3"/>
		<parent link="link_1"/>
	</joint>
</robot>
