<?xml version="1.0" ?>
<robot name="right-pull-door">
	<link name="base"/>
	<link name="link_0">
		<visual name="out-frame">
			<origin xyz="0 0 0"/>
			<geometry>
				<mesh filename="texture_dae/frame.dae" scale="0.8023904493137358 0.8023904493137358 0.8023904493137358"/>
			</geometry>
		</visual>
		<collision>
			<origin xyz="0 0 0"/>
			<geometry>
				<mesh filename="texture_dae/frame.dae" scale="0.8023904493137358 0.8023904493137358 0.8023904493137358"/>
			</geometry>
		</collision>
	</link>
	<joint name="joint_0" type="fixed">
		<origin rpy="1.570796326794897 0 -1.570796326794897" xyz="0 0 0"/>
		<child link="link_0"/>
		<parent link="base"/>
	</joint>
	<link name="link_1">
		<visual name="surf-board">
			<origin xyz="0.37226065927907914 -0.8182492597492138 0"/>
			<geometry>
				<mesh filename="texture_dae/board.dae" scale="0.8023904493137358 0.8023904493137358 0.8023904493137358"/>
			</geometry>
		</visual>
		<collision>
			<origin xyz="0.37226065927907914 -0.8182492597492138 0"/>
			<geometry>
				<mesh filename="texture_dae/board.dae" scale="0.8023904493137358 0.8023904493137358 0.8023904493137358"/>
			</geometry>
		</collision>
	</link>
	<joint name="joint_1" type="revolute">
		<origin xyz="-0.37226065927907914 0.8182492597492138 0"/>
		<axis xyz="0 -1 0"/>
		<child link="link_1"/>
		<parent link="link_0"/>
		<limit lower="0" upper="1.5079644737231006"/>
	</joint>
	<link name="link_2">
		<visual name="handle">
			<origin xyz="0 0 0"/>
			<geometry>
				<mesh filename="texture_dae/9962029.dae" scale="1.222368994223632 1.222368994223632 1.222368994223632"/>
			</geometry>
		</visual>
		<collision>
			<origin xyz="0 0 0"/>
			<geometry>
				<mesh filename="texture_dae/9962029.dae" scale="1.222368994223632 1.222368994223632 1.222368994223632"/>
			</geometry>
		</collision>
	</link>
	<joint name="joint_2" type="revolute">
		<origin xyz="0.6714978177312606 -0.9056112678517161 0.07096783359400255"/>
		<child link="link_2"/>
		<parent link="link_1"/>
		<axis xyz="0 0 1"/>
		<limit lower="0" upper="1.5079644737231006"/>
	</joint>
</robot>
