<?xml version="1.0" ?>
<robot name="right-pull-door">
	<link name="base"/>
	<link name="link_0">
		<visual name="out-frame">
			<origin xyz="0 0 0"/>
			<geometry>
				<mesh filename="texture_dae/frame.dae" scale="1.024851127275158 1.024851127275158 1.024851127275158"/>
			</geometry>
		</visual>
		<collision>
			<origin xyz="0 0 0"/>
			<geometry>
				<mesh filename="texture_dae/frame.dae" scale="1.024851127275158 1.024851127275158 1.024851127275158"/>
			</geometry>
		</collision>
	</link>
	<joint name="joint_0" type="fixed">
		<origin rpy="1.570796326794897 0 -1.570796326794897" xyz="0 0 0"/>
		<child link="link_0"/>
		<parent link="base"/>
	</joint>
	<link name="link_1">
		<visual name="surf-board">
			<origin xyz="0.47326599738277275 -0.9240887988804775 0"/>
			<geometry>
				<mesh filename="texture_dae/board.dae" scale="1.024851127275158 1.024851127275158 1.024851127275158"/>
			</geometry>
		</visual>
		<collision>
			<origin xyz="0.47326599738277275 -0.9240887988804775 0"/>
			<geometry>
				<mesh filename="texture_dae/board.dae" scale="1.024851127275158 1.024851127275158 1.024851127275158"/>
			</geometry>
		</collision>
	</link>
	<joint name="joint_1" type="revolute">
		<origin xyz="-0.47326599738277275 0.9240887988804775 0"/>
		<axis xyz="0 -1 0"/>
		<child link="link_1"/>
		<parent link="link_0"/>
		<limit lower="0" upper="1.5079644737231006"/>
	</joint>
	<link name="link_2">
		<visual name="handle">
			<origin xyz="0 0 0"/>
			<geometry>
				<mesh filename="texture_dae/9962039.dae" scale="1.2942130342378562 1.2942130342378562 1.2942130342378562"/>
			</geometry>
		</visual>
		<collision>
			<origin xyz="0 0 0"/>
			<geometry>
				<mesh filename="texture_dae/9962039.dae" scale="1.2942130342378562 1.2942130342378562 1.2942130342378562"/>
			</geometry>
		</collision>
	</link>
	<joint name="joint_2" type="revolute">
		<origin xyz="0.8689608918199028 -1.0228545654002308 0.0472825586221848"/>
		<child link="link_2"/>
		<parent link="link_1"/>
		<axis xyz="0 0 1"/>
		<limit lower="0" upper="1.5079644737231006"/>
	</joint>
</robot>
