<?xml version="1.0" ?>
<robot name="partnet_door_8897">
	<link name="base">
		<inertial>
			<origin xyz="0 0 0" rpy="0 0 0"/>
			<mass value="1.0"/>
			<inertia ixx="0.1" ixy="0" ixz="0" iyy="0.1" iyz="0" izz="0.1"/>
		</inertial>
	</link>
	<link name="link_0">
		<inertial>
			<origin xyz="0 0 0" rpy="0 0 0"/>
			<mass value="5.0"/>
			<inertia ixx="0.5" ixy="0" ixz="0" iyy="0.5" iyz="0" izz="0.5"/>
		</inertial>
		<visual name="outside_frame_1">
			<origin xyz="0 0 0"/>
			<geometry>
				<mesh filename="textured_objs/new_2.obj"/>
			</geometry>
		</visual>
		<visual name="outside_frame_2">
			<origin xyz="0 0 0"/>
			<geometry>
				<mesh filename="textured_objs/original_1.obj"/>
			</geometry>
		</visual>
		<visual name="outside_frame_3">
			<origin xyz="0 0 0"/>
			<geometry>
				<mesh filename="textured_objs/new_5.obj"/>
			</geometry>
		</visual>
		<collision>
			<origin xyz="0 0 0"/>
			<geometry>
				<mesh filename="textured_objs/new_2.obj"/>
			</geometry>
		</collision>
		<collision>
			<origin xyz="0 0 0"/>
			<geometry>
				<mesh filename="textured_objs/original_1.obj"/>
			</geometry>
		</collision>
		<collision>
			<origin xyz="0 0 0"/>
			<geometry>
				<mesh filename="textured_objs/new_5.obj"/>
			</geometry>
		</collision>
	</link>
	<joint name="joint_0" type="fixed">
		<origin rpy="1.570796326794897 0 -1.570796326794897" xyz="0 0 0"/>
		<child link="link_0"/>
		<parent link="base"/>
	</joint>
	<link name="link_1">
		<inertial>
			<origin xyz="0 0 0" rpy="0 0 0"/>
			<mass value="2.0"/>
			<inertia ixx="0.2" ixy="0" ixz="0" iyy="0.2" iyz="0" izz="0.2"/>
		</inertial>
		<visual name="surface_board_12">
			<origin xyz="0.3432525537649009 -0.828824 0.004683688059689217"/>
			<geometry>
				<mesh filename="textured_objs/new_3.obj"/>
			</geometry>
		</visual>
		<visual name="surface_board_13">
			<origin xyz="0.3432525537649009 -0.828824 0.004683688059689217"/>
			<geometry>
				<mesh filename="textured_objs/original_10.obj"/>
			</geometry>
		</visual>
		<visual name="surface_board_14">
			<origin xyz="0.3432525537649009 -0.828824 0.004683688059689217"/>
			<geometry>
				<mesh filename="textured_objs/original_11.obj"/>
			</geometry>
		</visual>
		<visual name="surface_board_15">
			<origin xyz="0.3432525537649009 -0.828824 0.004683688059689217"/>
			<geometry>
				<mesh filename="textured_objs/original_9.obj"/>
			</geometry>
		</visual>
		<collision>
			<origin xyz="0.3432525537649009 -0.828824 0.004683688059689217"/>
			<geometry>
				<mesh filename="textured_objs/new_3.obj"/>
			</geometry>
		</collision>
		<collision>
			<origin xyz="0.3432525537649009 -0.828824 0.004683688059689217"/>
			<geometry>
				<mesh filename="textured_objs/original_10.obj"/>
			</geometry>
		</collision>
		<collision>
			<origin xyz="0.3432525537649009 -0.828824 0.004683688059689217"/>
			<geometry>
				<mesh filename="textured_objs/original_11.obj"/>
			</geometry>
		</collision>
		<collision>
			<origin xyz="0.3432525537649009 -0.828824 0.004683688059689217"/>
			<geometry>
				<mesh filename="textured_objs/original_9.obj"/>
			</geometry>
		</collision>
	</link>
	<joint name="joint_1" type="revolute">
		<origin xyz="-0.3432525537649009 0.828824 -0.004683688059689217"/>
		<axis xyz="0 -1 0"/>
		<child link="link_1"/>
		<parent link="link_0"/>
		<limit lower="0.0" upper="1.5707963267948966"/>
	</joint>
	<link name="link_2">
		<inertial>
			<origin xyz="0 0 0" rpy="0 0 0"/>
			<mass value="1.5"/>
			<inertia ixx="0.15" ixy="0" ixz="0" iyy="0.15" iyz="0" izz="0.15"/>
		</inertial>
		<visual name="movable_part_11">
			<origin xyz="-0.27102619774442194 0.04494619130548938 -0.053442000000000434"/>
			<geometry>
				<mesh filename="textured_objs/original_19.obj"/>
			</geometry>
		</visual>
		<visual name="movable_part_12">
			<origin xyz="-0.27102619774442194 0.04494619130548938 -0.053442000000000434"/>
			<geometry>
				<mesh filename="textured_objs/original_18.obj"/>
			</geometry>
		</visual>
		<visual name="movable_part_9">
			<origin xyz="-0.27102619774442194 0.04494619130548938 -0.053442000000000434"/>
			<geometry>
				<mesh filename="textured_objs/original_7.obj"/>
			</geometry>
		</visual>
		<visual name="movable_part_10">
			<origin xyz="-0.27102619774442194 0.04494619130548938 -0.053442000000000434"/>
			<geometry>
				<mesh filename="textured_objs/original_8.obj"/>
			</geometry>
		</visual>
		<collision>
			<origin xyz="-0.27102619774442194 0.04494619130548938 -0.053442000000000434"/>
			<geometry>
				<mesh filename="textured_objs/original_19.obj"/>
			</geometry>
		</collision>
		<collision>
			<origin xyz="-0.27102619774442194 0.04494619130548938 -0.053442000000000434"/>
			<geometry>
				<mesh filename="textured_objs/original_18.obj"/>
			</geometry>
		</collision>
		<collision>
			<origin xyz="-0.27102619774442194 0.04494619130548938 -0.053442000000000434"/>
			<geometry>
				<mesh filename="textured_objs/original_7.obj"/>
			</geometry>
		</collision>
		<collision>
			<origin xyz="-0.27102619774442194 0.04494619130548938 -0.053442000000000434"/>
			<geometry>
				<mesh filename="textured_objs/original_8.obj"/>
			</geometry>
		</collision>
	</link>
	<joint name="joint_2" type="revolute">
		<origin xyz="0.6142787515093229 -0.7877866832361299 0.06223562679904443"/>
		<axis xyz="0 0 1"/>
		<child link="link_2"/>
		<parent link="link_1"/>
		<limit lower="0.0" upper="1.5707963267948966"/>
	</joint>
</robot>
