<?xml version="1.0" ?>
<robot name="right-pull-door">
	<link name="base"/>
	<link name="link_0">
		<visual name="out-frame">
			<origin xyz="0 0 0"/>
			<geometry>
				<mesh filename="texture_dae/frame.dae" scale="0.7727926928934716 0.7727926928934716 0.7727926928934716"/>
			</geometry>
		</visual>
		<collision>
			<origin xyz="0 0 0"/>
			<geometry>
				<mesh filename="texture_dae/frame.dae" scale="0.7727926928934716 0.7727926928934716 0.7727926928934716"/>
			</geometry>
		</collision>
	</link>
	<joint name="joint_0" type="fixed">
		<origin rpy="1.570796326794897 0 -1.570796326794897" xyz="0 0 0"/>
		<child link="link_0"/>
		<parent link="base"/>
	</joint>
	<link name="link_1">
		<visual name="surf-board">
			<origin xyz="0.43107872977436495 -0.8212555453850839 0"/>
			<geometry>
				<mesh filename="texture_dae/board.dae" scale="0.7727926928934716 0.7727926928934716 0.7727926928934716"/>
			</geometry>
		</visual>
		<collision>
			<origin xyz="0.43107872977436495 -0.8212555453850839 0"/>
			<geometry>
				<mesh filename="texture_dae/board.dae" scale="0.7727926928934716 0.7727926928934716 0.7727926928934716"/>
			</geometry>
		</collision>
	</link>
	<joint name="joint_1" type="revolute">
		<origin xyz="-0.43107872977436495 0.8212555453850839 0"/>
		<axis xyz="0 -1 0"/>
		<child link="link_1"/>
		<parent link="link_0"/>
		<limit lower="0" upper="1.5079644737231006"/>
	</joint>
	<link name="link_2">
		<visual name="handle">
			<origin xyz="0 0 0"/>
			<geometry>
				<mesh filename="texture_dae/9960006.dae" scale="2.168468561311864 2.168468561311864 2.168468561311864"/>
			</geometry>
		</visual>
		<collision>
			<origin xyz="0 0 0"/>
			<geometry>
				<mesh filename="texture_dae/9960006.dae" scale="2.168468561311864 2.168468561311864 2.168468561311864"/>
			</geometry>
		</collision>
	</link>
	<joint name="joint_2" type="revolute">
		<origin xyz="0.7828395534710215 -0.8695793994499799 0.015916213578276408"/>
		<child link="link_2"/>
		<parent link="link_1"/>
		<axis xyz="0 0 1"/>
		<limit lower="0" upper="1.5079644737231006"/>
	</joint>
</robot>
