<?xml version="1.0" ?>
<robot name="right-pull-door">
	<link name="base"/>
	<link name="link_0">
		<visual name="out-frame">
			<origin xyz="0 0 0"/>
			<geometry>
				<mesh filename="texture_dae/frame.dae" scale="0.8189554583525107 0.8189554583525107 0.8189554583525107"/>
			</geometry>
		</visual>
		<collision>
			<origin xyz="0 0 0"/>
			<geometry>
				<mesh filename="texture_dae/frame.dae" scale="0.8189554583525107 0.8189554583525107 0.8189554583525107"/>
			</geometry>
		</collision>
	</link>
	<joint name="joint_0" type="fixed">
		<origin rpy="1.570796326794897 0 -1.570796326794897" xyz="0 0 0"/>
		<child link="link_0"/>
		<parent link="base"/>
	</joint>
	<link name="link_1">
		<visual name="surf-board">
			<origin xyz="0.3299410238065448 -0.8491683641712733 0"/>
			<geometry>
				<mesh filename="texture_dae/board.dae" scale="0.8189554583525107 0.8189554583525107 0.8189554583525107"/>
			</geometry>
		</visual>
		<collision>
			<origin xyz="0.3299410238065448 -0.8491683641712733 0"/>
			<geometry>
				<mesh filename="texture_dae/board.dae" scale="0.8189554583525107 0.8189554583525107 0.8189554583525107"/>
			</geometry>
		</collision>
	</link>
	<joint name="joint_1" type="revolute">
		<origin xyz="-0.3299410238065448 0.8491683641712733 0"/>
		<axis xyz="0 -1 0"/>
		<child link="link_1"/>
		<parent link="link_0"/>
		<limit lower="0" upper="1.5079644737231006"/>
	</joint>
	<link name="link_2">
		<visual name="handle">
			<origin xyz="0 0 0"/>
			<geometry>
				<mesh filename="texture_dae/9960025-handle-right.dae" scale="1.2953105643978882 1.2953105643978882 1.2953105643978882"/>
			</geometry>
		</visual>
		<collision>
			<origin xyz="0 0 0"/>
			<geometry>
				<mesh filename="texture_dae/9960025-handle-right.dae" scale="1.2953105643978882 1.2953105643978882 1.2953105643978882"/>
			</geometry>
		</collision>
	</link>
	<joint name="joint_2" type="revolute">
		<origin xyz="0 0 0"/>
		<child link="link_2"/>
		<parent link="link_3"/>
		<axis xyz="0 0 1"/>
		<limit lower="0" upper="1.5079644737231006"/>
	</joint>
	<link name="link_3">
		<visual name="lock">
			<origin xyz="0 0 0"/>
			<geometry>
				<mesh filename="texture_dae/9960025-lock-right.dae" scale="1.2953105643978882 1.2953105643978882 1.2953105643978882"/>
			</geometry>
		</visual>
		<collision>
			<origin xyz="0 0 0"/>
			<geometry>
				<mesh filename="texture_dae/9960025-lock-right.dae" scale="1.2953105643978882 1.2953105643978882 1.2953105643978882"/>
			</geometry>
		</collision>
	</link>
	<joint name="joint_3" type="fixed">
		<origin xyz="0.5793236201129282 -0.9471523824384336 0.027319542902807352"/>
		<child link="link_3"/>
		<parent link="link_1"/>
	</joint>
</robot>
