<?xml version="1.0" ?>
<robot name="right-pull-door">
	<link name="base"/>
	<link name="link_0">
		<visual name="out-frame">
			<origin xyz="0 0 0"/>
			<geometry>
				<mesh filename="texture_dae/frame.dae" scale="0.8837270872727645 0.8837270872727645 0.8837270872727645"/>
			</geometry>
		</visual>
		<collision>
			<origin xyz="0 0 0"/>
			<geometry>
				<mesh filename="texture_dae/frame.dae" scale="0.8837270872727645 0.8837270872727645 0.8837270872727645"/>
			</geometry>
		</collision>
	</link>
	<joint name="joint_0" type="fixed">
		<origin rpy="1.570796326794897 0 -1.570796326794897" xyz="0 0 0"/>
		<child link="link_0"/>
		<parent link="base"/>
	</joint>
	<link name="link_1">
		<visual name="surf-board">
			<origin xyz="0.33678483597120745 -0.8826866484217946 0"/>
			<geometry>
				<mesh filename="texture_dae/board.dae" scale="0.8837270872727645 0.8837270872727645 0.8837270872727645"/>
			</geometry>
		</visual>
		<collision>
			<origin xyz="0.33678483597120745 -0.8826866484217946 0"/>
			<geometry>
				<mesh filename="texture_dae/board.dae" scale="0.8837270872727645 0.8837270872727645 0.8837270872727645"/>
			</geometry>
		</collision>
	</link>
	<joint name="joint_1" type="revolute">
		<origin xyz="-0.33678483597120745 0.8826866484217946 0"/>
		<axis xyz="0 -1 0"/>
		<child link="link_1"/>
		<parent link="link_0"/>
		<limit lower="0" upper="1.5079644737231006"/>
	</joint>
	<link name="link_2">
		<visual name="handle">
			<origin xyz="0 0 0"/>
			<geometry>
				<mesh filename="texture_dae/9960022.dae" scale="1.3242535668225608 1.3242535668225608 1.3242535668225608"/>
			</geometry>
		</visual>
		<collision>
			<origin xyz="0 0 0"/>
			<geometry>
				<mesh filename="texture_dae/9960022.dae" scale="1.3242535668225608 1.3242535668225608 1.3242535668225608"/>
			</geometry>
		</collision>
	</link>
	<joint name="joint_2" type="revolute">
		<origin xyz="0.5934000323636804 -0.9957334196364709 0.013949457871978412"/>
		<child link="link_2"/>
		<parent link="link_1"/>
		<axis xyz="0 0 1"/>
		<limit lower="0" upper="1.5079644737231006"/>
	</joint>
</robot>
